package me.yonghong.springboot.lab.kotlininaction.chapter06

import kotlinx.coroutines.*
import kotlin.system.measureTimeMillis

fun main() = runBlocking<Unit> {
    var time = measureTimeMillis {
        val one = doSomethingUsefulOne()
        val two = doSomethingUsefulTwo()
        println("The answer is ${one + two}")
    }
    println("Completed in $time ms")

    time = measureTimeMillis {
        val one = async { doSomethingUsefulOne() }
        val two = async { doSomethingUsefulTwo() }
        println("The answer is ${one.await() + two.await()}")
    }
    println("Completed in $time ms")


    time = measureTimeMillis {
        val one = async(start = CoroutineStart.LAZY) { doSomethingUsefulOne() }
        val two = async(start = CoroutineStart.LAZY) { doSomethingUsefulTwo() }
        // 执行一些计算
        delay(3000L)
//        one.start() // 启动第一个
//        two.start() // 启动第二个
        println("The answer is ${one.await() + two.await()}")
    }
    println("Completed in $time ms")

    time = measureTimeMillis {
        // 我们可以在协程外面启动异步执行
        val one = somethingUsefulOneAsync()
        val two = somethingUsefulTwoAsync()
        // 但是等待结果必须调用其它的挂起或者阻塞
        // 当我们等待结果的时候，这里我们使用 `runBlocking { …… }` 来阻塞主线程
        runBlocking {
            println("The answer is ${one.await() + two.await()}")
        }
    }
    println("Completed in $time ms")

    time = measureTimeMillis {
        println("The answer is ${concurrentSum()}")
    }
    println("Completed in $time ms")

    try {
        failedConcurrentSum()
    } catch(e: ArithmeticException) {
        println("Computation failed with ArithmeticException")
    }
}

suspend fun doSomethingUsefulOne(): Int {
    delay(1000L) // 假设我们在这里做了些有用的事
    return 13
}

suspend fun doSomethingUsefulTwo(): Int {
    delay(1000L) // 假设我们在这里也做了一些有用的事
    return 29
}

// somethingUsefulOneAsync 函数的返回值类型是 Deferred<Int>
fun somethingUsefulOneAsync() = GlobalScope.async {
    doSomethingUsefulOne()
}

// somethingUsefulTwoAsync 函数的返回值类型是 Deferred<Int>
fun somethingUsefulTwoAsync() = GlobalScope.async {
    doSomethingUsefulTwo()
}

suspend fun concurrentSum(): Int = coroutineScope {
    val one = async { doSomethingUsefulOne() }
    val two = async { doSomethingUsefulTwo() }
    one.await() + two.await()
}

suspend fun failedConcurrentSum(): Int = coroutineScope {
    val one = async<Int> {
        try {
            delay(Long.MAX_VALUE) // 模拟一个长时间的运算
            42
        } finally {
            println("First child was cancelled")
        }
    }
    val two = async<Int> {
        println("Second child throws an exception")
        throw ArithmeticException()
    }
    one.await() + two.await()
}